2024-05-13 16:21:28,935 Minimum price: 10, Maximum price: 350
Traceback (most recent call last):
  File "/home/chelzeemares/miniconda3/envs/mlflow-da93339ed90e31f137db8dabdae14e69a71f1301/lib/python3.9/site-packages/pandas/core/indexes/base.py", line 2895, in get_loc
    return self._engine.get_loc(casted_key)
  File "pandas/_libs/index.pyx", line 70, in pandas._libs.index.IndexEngine.get_loc
  File "pandas/_libs/index.pyx", line 101, in pandas._libs.index.IndexEngine.get_loc
  File "pandas/_libs/hashtable_class_helper.pxi", line 1675, in pandas._libs.hashtable.PyObjectHashTable.get_item
  File "pandas/_libs/hashtable_class_helper.pxi", line 1683, in pandas._libs.hashtable.PyObjectHashTable.get_item
KeyError: 'none'
The above exception was the direct cause of the following exception:
Traceback (most recent call last):
  File "/home/chelzeemares/Project-Build-an-ML-Pipeline-Starter/src/train_random_forest/run.py", line 297, in <module>
    go(args)
  File "/home/chelzeemares/Project-Build-an-ML-Pipeline-Starter/src/train_random_forest/run.py", line 64, in go
    X, y, test_size=args.val_size, stratify=X[args.stratify_by], random_state=args.random_seed
  File "/home/chelzeemares/miniconda3/envs/mlflow-da93339ed90e31f137db8dabdae14e69a71f1301/lib/python3.9/site-packages/pandas/core/frame.py", line 2906, in __getitem__
    indexer = self.columns.get_loc(key)
  File "/home/chelzeemares/miniconda3/envs/mlflow-da93339ed90e31f137db8dabdae14e69a71f1301/lib/python3.9/site-packages/pandas/core/indexes/base.py", line 2897, in get_loc
    raise KeyError(key) from err
KeyError: 'none'